<!DOCTYPE html>
<html lang="en">
<head>
    <meta charset="UTF-8">
    <meta name="viewport" content="width=device-width, initial-scale=1.0">
    <title>Promise</title>
</head>
<body>

    <div onClick = {promiseClick}>开始异步请求</div>

    <script>
        /**
        * 1.什么是Promise
        * Promise 是异步编程的一种解决办法，其实是一个构造函数，自己身上有all、reject、resolve这几个方法，原型上有then、catch等方法。
        * 
        * Promise对象有以下两个特点：
        * 1）对象的状态不受外界影响。Promise对象代表一个异步操作，有三种状态：pending(进行中)、fulfilled(已成功)和rejected(已失败)。只有异步操作的结果，可以决定当前是哪一种状态，任何其他操作都无法改变这个状态。
        * 2）一旦状态改变，就不会再变，任何时候都可以得到这个结果。Promise对象的状态改变，只有两种可能：从pending变为fulfilled和从pending变为rejected。只要这两种情况发生，状态就凝固了，不会在变了，会一直保持这个结果，这时就称为resolved(已定型)。如果改变已经发生了，你在对Promise对象添加回调函数，也会立即得到这个结果。这与事件(Event)完全不同，事件的特点是，如果你错过了它，再去监听，是得不到结果的。
        */

        // 下面先 new 一个 Promise

        // let p =new Promise(function(resolve,reject){
        //     // 做一些异步操作
        //     setTimeout(function(){
        //         console.log('执行完成Promise');
        //         resolve('要返回的数据可以任何数据例如接口返回数据');
        //     },2000)
        // })

        // 刷新页面控制台会打印出------执行完成Promise

        // 执行过程是：执行了一个异步操作，也就是setTimeout,两秒后，输出“执行完成Promise”，并且调用resolve方法。
        // 注意！我们只是 new 了一个对象，并没有调用它，我们传进去的函数就已经执行了，这是需要注意的一个细节。所以我们用Promise的时候一般是包含在一个函数中，在需要的时候去运行这个函数。
        
        
        // <div onClick = {promiseClick}>开始异步请求</div>
        // const promiseClick=()=>{
        //     console.log('点击方法被调用')
        //     let p = new Promise(function(resolve, reject){
        //         //做一些异步操作
        //         setTimeout(function(){
        //             console.log('执行完成Promise');
        //             resolve('要返回的数据可以任何数据例如接口返回数据');
        //         },2000);
        //     })
        //     return p
        // }
        
        // 刷新页面的时候没有任何反应，但是点击后控制台会打印出------点击方法被调用   执行完成Promise

        /**
        * 当放在函数里面的时候只有调用的时候才会被执行
        * 接下来解决两个问题：
        * 1.为什么要放在函数里面
        * 2.resolve是什么
        * 我们包装好的函数最后，会 return 出 Promise 对象，也就是说，执行这个函数我们得到了一个Promise对象。接下来就可以用 Promise 对象上有 then、catch方法了，这是就是Promise的强大之处
        */

        // promiseClick().then(function(data){
        //     console.log(data)
        //     // 后面可以用传过来的数据做些其他操作
        //     // ......
        // })

        // 控制台输出------点击方法被调用   执行完成Promise   要返回的数据可以任何数据例如接口返回数据

        /**
        * 先是方法被调用执行了Promise，最后执行了Promise的then方法，then方法是一个函数接收一个参数是接收resolve返回的数据这时就输出了‘要返回的数据可以任何数据例如接口返回数据’
        * then里面的函数跟我们平时的回调函数是一个意思，能够在promiseClick这个异步任务执行完成之后被执行。这就是Promise的作用了，简单来讲，就是能把原来的回调写法分离出来，在异步操作执行完后，用链式调用的方式执行回调函数。
        * 虽然这个和写一个回调函数没有什么区别，但是如果是多层回调呢？如果callback也是一个异步操作，而且执行完后也需要有相应的回调函数，该怎么办呢？总不能再定义一个callback2，然后该callback传进去。而Promise的优势在于，可以再then方法中继续写Promise对象并返回，然后继续调用then来进行回调操作。
        * 所以：精髓在于：Promise只是能够简化层层回调的写法，而实际上，Promise的精髓是“状态”，用维护状态、传递状态的方式来使得回调函数能够及时调用，它比传递callback函数要简单、灵活的多。
        */

        // promiseClick().then(function(data){
        //     console.log(data);
        //     return runAsync2();
        // }).then(function(data){
        //     console.log(data);
        //     return runAsync3();
        // }).then(function(data){
        //     console.log(data);
        // })

        // 这样能够按顺序，每隔两秒输出每个异步回调中的内容，在runAsync2中传给resolve的数据，能在接下来的then方法中拿到。

        // 2.reject的用法
        // 以上是对Promise的resolve用法进行了解释，相当于resolve是对Promise成功时候的回调，他把Promise的状态修改为fullfiled，那么，reject就是失败的时候的回调，他把Promise的状态修改为rejected，这样我们在then中就能捕捉到，然后执行“失败”情况的回调

        // function promiseClick(){
        //     let p = new Promise(function(resolve,reject){
        //         setTimeout(function(){
        //             var num = Math.ceil(Math.random()*20); //生成1-10的随机数
        //             console.log('随机数生成的值：',num)
        //             if(num<=10){
        //                 resolve(num);
        //             }else{
        //                 reject('数字大于10了即将执行失败回调');
        //             }
        //         },2000)
        //     })
        //     return p
        // }

        // promiseClick().then(
        //     function(data){
        //         console.log('resolved成功回调');
        //         console.log('成功回调接收的值：',data)
        //     },
        //     function(reason,data){
        //         console.log('rejected失败回调');
        //         console.log('失败执行回调抛出失败原因：',reason);
        //     }
        // )

        // 执行结果
        /**
        * 随机数生成的值： 15
        * rejected失败回调
        * 失败执行回调抛出失败原因： 数字大于10了即将执行失败回调
        *------------------------------------------------
        * 随机数生成的值： 9
        * resolved成功回调
        * 成功回调接收的值： 9
        * 
        * 以上为执行了两次的结果
        */

        /**
        * 以上代码：调用promiseClick方法执行，2秒后获取一个随机数，如果小于10，算成功，调用resolve修改Promise的状态为fullfiled。否则认为是“失败”了，调用reject并传递一个参数，作为失败的原因。并将状态改为rejected
        * 运行promiseClick并且在then中传了两个参数，这两个参数分别是两个函数，then方法可以接受两个参数，第一个对应resolve的回调，第二个对应reject的回调。（也就是说then方法中接收两个回调，一个成功的回调函数，一个失败的回调函数，并且能在回调函数中拿到成功的数据和失败的原因），所以我们能够分别拿到成功和失败传过来的数据就有以上的运行结果
        */

        // 3.catch的用法
        // 与Promised对象方法then方法并行的一个方法就是catch,与try catch类似，catch就是用来捕获异常的，也就是和then方法中接受的第二参数rejected的回调是一样的

        // function promiseClick(){
        //     let p = new Promise(function(resolve, reject){
        //         setTimeout(function(){
        //             var num = Math.ceil(Math.random()*20); // 生成1-10的随机数
        //             console.log('随机数生成的值：',num)
        //             if(num<=10){
        //                 resolve(num);
        //             }else{
        //                 reject('数字大于10了即将执行失败回调')
        //             }
        //         },2000)
        //     })
        //     return p;
        // }

        // promiseClick().then(
        //     function(data){
        //         console.log('resolved成功回调');
        //         console.log('成功回调接收的值：',data);
        //     }
        // ).catch(function(reason, data){
        //     console.log('catch到rejected失败回调');
        //     console.log('catch失败执行回调抛出失败原因：', reason);
        // })

        // 执行结果
        /**
        * 随机数生成的值： 4
        * resolved成功回调
        * 成功回调接收的值： 4
        *------------------------------------------------
        * 随机数生成的值： 16
        * catch到rejected失败回调
        * catch失败执行回调抛出失败原因： 数字大于10了即将执行失败回调
        * 
        * 以上为执行了两次的结果
        */

        // 效果和写在then的第二个参数里面一样。它将大于10 的情况下的失败回调的原因输出，但是，它还有另外一个作用：在执行resolve的回调（也就是上面then中的第一个参数）时，如果抛出异常了（代码出错了），那么并不会报错卡死js，而时会进到这个catch方法中。
        function promiseClick(){
            let p = new Promise(function(resolve, reject){
                setTimeout(function(){
                    var num = Math.ceil(Math.random()*20); // 生成1-10的随机数
                    console.log('随机数生成的值：',num)
                    if(num<=10){
                        resolve(num);
                    } else {
                        reject('数字大于10了即将执行失败回调')
                    }
                },2000)
            })
            return p
        }
        
        promiseClick().then(
            function(data){
                console.log('resolvec成功回调');
                console.log('成功回调接收的值：',data)
                console.log(noData);
            }
        ).catch(function(reason, data){
            console.log('catch到rejected失败回调');
            console.log('catch失败执行回调抛出失败原因：',reason);
        })

        // 执行结果
        /**
        * catch到rejected失败回调
        * catch失败执行回调抛出失败原因： ReferenceError: noData is not defined at study09.html:196
        */

        // 在resolve的回调中，我们console.log(noData)；而noData这个变量是没有被定义的。如果我们不用Promise，代码运行到这里就直接在控制台报错了，不往下运行了。但是在这里，会得到上面结果，也就是说进到了catch方法里面去了，而且把错误原因传到了reason参数中。即便是有错误的代码也不会报错了








    </script>
</body>
</html>